<?xml version="1.0"?>
<robot name="artemis_arena">

    <link name = "arena_link">

        <!-- core -->
        <visual name = "arena_visual">
            <geometry>
                <mesh filename = "file://$(find csm_gz_sim)/worlds/meshes/artemis-arena.dae" scale = "1 1 1"/>
            </geometry>
        </visual>
        <collision name = "arena_collision">
            <geometry>
                <mesh filename = "file://$(find csm_gz_sim)/worlds/meshes/artemis-arena-collision.stl" scale = "1 1 1"/>
            </geometry>
        </collision>

        <!-- Terrain -->
        <visual name = "terrain_visual">
            <origin xyz = "3.61 2.67 0.4" rpy = "0 0 3.1415926"/>
            <geometry>
                <mesh filename = "file://$(find csm_gz_sim)/worlds/meshes/lunar-terrain.dae" scale = "2 2 2"/>
            </geometry>
        </visual>
        <collision name = "terrain_collision">
            <origin xyz = "3.61 2.67 0.4" rpy = "0 0 3.1415926"/>
            <geometry>
                <mesh filename = "file://$(find csm_gz_sim)/worlds/meshes/lunar-terrain.stl" scale = "2 2 2"/>
            </geometry>
        </collision>

        <!-- Env room -->
        <visual name = "arena_env_visual">
            <geometry>
                <mesh filename = "file://$(find csm_gz_sim)/worlds/meshes/artemis-arena-env.dae" scale = "1 1 1"/>
            </geometry>
        </visual>
        <collision name = "arena_env_collision">
            <geometry>
                <mesh filename = "file://$(find csm_gz_sim)/worlds/meshes/artemis-arena-env.dae" scale = "1 1 1"/>
            </geometry>
        </collision>

    </link>

    <joint name = "rock1_joint" type = "floating">
        <parent link = "arena_link"/>
        <child link = "rock1"/>
        <origin xyz = "6 3.5 0.5"/>
    </joint>
    <link name = "rock1">
        <inertial>
            <origin xyz = "0 0 0"/>
            <mass value = "15.0"/>
        </inertial>
        <visual name = "rock1_visual">
            <geometry>
                <mesh filename = "./meshes/rock1.dae" scale = "0.5 0.5 0.5"/>
            </geometry>
        </visual>
        <collision name = "rock1_collision">
            <geometry>
                <mesh filename = "./meshes/rock1.dae" scale = "0.5 0.5 0.5"/>
            </geometry>
        </collision>
    </link>

    <joint name = "rock1_joint" type = "floating">
        <parent link = "arena_link"/>
        <child link = "rock1"/>
        <origin xyz = "6 3.5 0.5"/>
    </joint>
    <link name = "rock1">
        <inertial>
            <origin xyz = "0 0 0"/>
            <mass value = "15.0"/>
        </inertial>
        <visual name = "rock1_visual">
            <geometry>
                <mesh filename = "./meshes/rock1.dae" scale = "0.5 0.5 0.5"/>
            </geometry>
        </visual>
        <collision name = "rock1_collision">
            <geometry>
                <mesh filename = "./meshes/rock1.dae" scale = "0.5 0.5 0.5"/>
            </geometry>
        </collision>
    </link>

    <joint name = "rock2_joint" type = "floating">
        <parent link = "arena_link"/>
        <child link = "rock2"/>
        <origin xyz = "5.5 2.5 0.5"/>
    </joint>
    <link name = "rock2">
        <inertial>
            <origin xyz = "0 0 0"/>
            <mass value = "30.0"/>
        </inertial>
        <visual name = "rock2_visual">
            <geometry>
                <mesh filename = "./meshes/rock2.dae" scale = "0.3 0.3 0.3"/>
            </geometry>
        </visual>
        <collision name = "rock2_collision">
            <geometry>
                <mesh filename = "./meshes/rock2.dae" scale = "0.3 0.3 0.3"/>
            </geometry>
        </collision>
    </link>

    <joint name = "rock3_joint" type = "floating">
        <parent link = "arena_link"/>
        <child link = "rock3"/>
        <origin xyz = "0.8 4.0 0.5"/>
    </joint>
    <link name = "rock3">
        <inertial>
            <origin xyz = "0 0 0"/>
            <mass value = "25.0"/>
        </inertial>
        <visual name = "rock3_visual">
            <geometry>
                <mesh filename = "./meshes/rock3.dae" scale = "0.2 0.2 0.2"/>
            </geometry>
        </visual>
        <collision name = "rock3_collision">
            <geometry>
                <mesh filename = "./meshes/rock3.dae" scale = "0.2 0.2 0.2"/>
            </geometry>
        </collision>
    </link>

</robot>
